<?xml version="1.0" ?>
<!-- =================================================================================== -->
<!-- |    This document was autogenerated by xacro from /home/v4hn/ros/one/constructor/src/cu_ur5e/cu_ur5e_description/robots/basic_setup.urdf.xacro | -->
<!-- |    EDITING THIS FILE BY HAND IS NOT RECOMMENDED                                 | -->
<!-- =================================================================================== -->
<robot name="cu_ur5e">
    <!--
    Base UR robot series xacro macro.

    NOTE: this is NOT a URDF. It cannot directly be loaded by consumers
    expecting a flattened '.urdf' file. See the top-level '.xacro' for that
    (but note: that .xacro must still be processed by the xacro command).

    For use in '.launch' files: use one of the 'load_urX.launch' convenience
    launch files.

    This file models the base kinematic chain of a UR robot, which then gets
    parameterised by various configuration files to convert it into a UR3(e),
    UR5(e), UR7e, UR10(e), UR12e UR16e, UR15, UR20 or UR30.

    NOTE: the default kinematic parameters (ie: link lengths, frame locations,
    offets, etc) do not correspond to any particular robot. They are defaults
    only. There WILL be non-zero offsets between the Forward Kinematics results
    in TF (ie: robot_state_publisher) and the values reported by the Teach
    Pendant.

    For accurate (and robot-specific) transforms, the 'kinematics_parameters_file'
    parameter MUST point to a .yaml file containing the appropriate values for
    the targetted robot.

    If using the UniversalRobots/Universal_Robots_ROS_Driver, follow the steps
    described in the readme of that repository to extract the kinematic
    calibration from the controller and generate the required .yaml file.

    Main author of the migration to yaml configs: Ludovic Delval.

    Contributors to previous versions (in no particular order):

     - Felix Messmer
     - Kelsey Hawkins
     - Wim Meeussen
     - Shaun Edwards
     - Nadia Hammoudeh Garcia
     - Dave Hershberger
     - G. vd. Hoorn
     - Philip Long
     - Dave Coleman
     - Miguel Prada
     - Mathias Luedtke
     - Marcel Schnirring
     - Felix von Drigalski
     - Felix Exner
     - Jimmy Da Silva
     - Ajit Krisshna N L
     - Muhammad Asif Rana
  -->
    <!--
    NOTE: the macro defined in this file is NOT part of the public API of this
          package. Users CANNOT rely on this file being available, or stored in
          this location. Nor can they rely on the existence of the macro.
  -->
    <transmission name="arm_shoulder_pan_trans">
        <type>transmission_interface/SimpleTransmission</type>
        <joint name="arm_shoulder_pan_joint">
            <hardwareInterface>hardware_interface/PositionJointInterface</hardwareInterface>
        </joint>
        <actuator name="arm_shoulder_pan_motor">
            <mechanicalReduction>1</mechanicalReduction>
            <hardwareInterface>hardware_interface/EffortJointInterface</hardwareInterface>
        </actuator>
    </transmission>
    <transmission name="arm_shoulder_lift_trans">
        <type>transmission_interface/SimpleTransmission</type>
        <joint name="arm_shoulder_lift_joint">
            <hardwareInterface>hardware_interface/PositionJointInterface</hardwareInterface>
        </joint>
        <actuator name="arm_shoulder_lift_motor">
            <mechanicalReduction>1</mechanicalReduction>
            <hardwareInterface>hardware_interface/EffortJointInterface</hardwareInterface>
        </actuator>
    </transmission>
    <transmission name="arm_elbow_trans">
        <type>transmission_interface/SimpleTransmission</type>
        <joint name="arm_elbow_joint">
            <hardwareInterface>hardware_interface/PositionJointInterface</hardwareInterface>
        </joint>
        <actuator name="arm_elbow_motor">
            <mechanicalReduction>1</mechanicalReduction>
            <hardwareInterface>hardware_interface/EffortJointInterface</hardwareInterface>
        </actuator>
    </transmission>
    <transmission name="arm_wrist_1_trans">
        <type>transmission_interface/SimpleTransmission</type>
        <joint name="arm_wrist_1_joint">
            <hardwareInterface>hardware_interface/PositionJointInterface</hardwareInterface>
        </joint>
        <actuator name="arm_wrist_1_motor">
            <mechanicalReduction>1</mechanicalReduction>
            <hardwareInterface>hardware_interface/EffortJointInterface</hardwareInterface>
        </actuator>
    </transmission>
    <transmission name="arm_wrist_2_trans">
        <type>transmission_interface/SimpleTransmission</type>
        <joint name="arm_wrist_2_joint">
            <hardwareInterface>hardware_interface/PositionJointInterface</hardwareInterface>
        </joint>
        <actuator name="arm_wrist_2_motor">
            <mechanicalReduction>1</mechanicalReduction>
            <hardwareInterface>hardware_interface/EffortJointInterface</hardwareInterface>
        </actuator>
    </transmission>
    <transmission name="arm_wrist_3_trans">
        <type>transmission_interface/SimpleTransmission</type>
        <joint name="arm_wrist_3_joint">
            <hardwareInterface>hardware_interface/PositionJointInterface</hardwareInterface>
        </joint>
        <actuator name="arm_wrist_3_motor">
            <mechanicalReduction>1</mechanicalReduction>
            <hardwareInterface>hardware_interface/EffortJointInterface</hardwareInterface>
        </actuator>
    </transmission>
    <!-- links: main serial chain -->
    <link name="arm_base_link" />
    <link name="arm_base_link_inertia">
        <visual>
            <origin rpy="0 0 3.141592653589793" xyz="0 0 0" />
            <geometry>
                <mesh filename="package://ur_description/meshes/ur5e/visual/base.dae" />
            </geometry>
            <material name="LightGrey">
                <color rgba="0.7 0.7 0.7 1.0" />
            </material>
        </visual>
        <collision>
            <origin rpy="0 0 3.141592653589793" xyz="0 0 0" />
            <geometry>
                <mesh filename="package://ur_description/meshes/ur5e/collision/base.stl" />
            </geometry>
        </collision>
        <inertial>
            <mass value="4.0" />
            <origin rpy="0 0 0" xyz="0 0 0" />
            <inertia ixx="0.00443333156" ixy="0.0" ixz="0.0" iyy="0.00443333156" iyz="0.0" izz="0.0072" />
        </inertial>
    </link>
    <link name="arm_shoulder_link">
        <visual>
            <origin rpy="0 0 3.141592653589793" xyz="0 0 0" />
            <geometry>
                <mesh filename="package://ur_description/meshes/ur5e/visual/shoulder.dae" />
            </geometry>
            <material name="LightGrey">
                <color rgba="0.7 0.7 0.7 1.0" />
            </material>
        </visual>
        <collision>
            <origin rpy="0 0 3.141592653589793" xyz="0 0 0" />
            <geometry>
                <mesh filename="package://ur_description/meshes/ur5e/collision/shoulder.stl" />
            </geometry>
        </collision>
        <inertial>
            <mass value="3.761" />
            <origin rpy="1.570796326794897 0 0" xyz="0.0 -0.00193 -0.02561" />
            <inertia ixx="0.0070021" ixy="7.3e-07" ixz="-1.053e-05" iyy="0.00648091" iyz="0.00049994" izz="0.00657286" />
        </inertial>
    </link>
    <link name="arm_upper_arm_link">
        <visual>
            <origin rpy="1.5707963267948966 0 -1.5707963267948966" xyz="0 0 0.138" />
            <geometry>
                <mesh filename="package://ur_description/meshes/ur5e/visual/upperarm.dae" />
            </geometry>
            <material name="LightGrey">
                <color rgba="0.7 0.7 0.7 1.0" />
            </material>
        </visual>
        <collision>
            <origin rpy="1.5707963267948966 0 -1.5707963267948966" xyz="0 0 0.138" />
            <geometry>
                <mesh filename="package://ur_description/meshes/ur5e/collision/upperarm.stl" />
            </geometry>
        </collision>
        <inertial>
            <mass value="8.058" />
            <origin rpy="0 0 0" xyz="-0.2125 0.0 0.11336" />
            <inertia ixx="0.01505885" ixy="-5.4e-05" ixz="5.63e-06" iyy="0.33388086" iyz="-1.81e-06" izz="0.33247207" />
        </inertial>
    </link>
    <link name="arm_forearm_link">
        <visual>
            <origin rpy="1.5707963267948966 0 -1.5707963267948966" xyz="0 0 0.007" />
            <geometry>
                <mesh filename="package://ur_description/meshes/ur5e/visual/forearm.dae" />
            </geometry>
            <material name="LightGrey">
                <color rgba="0.7 0.7 0.7 1.0" />
            </material>
        </visual>
        <collision>
            <origin rpy="1.5707963267948966 0 -1.5707963267948966" xyz="0 0 0.007" />
            <geometry>
                <mesh filename="package://ur_description/meshes/ur5e/collision/forearm.stl" />
            </geometry>
        </collision>
        <inertial>
            <mass value="2.846" />
            <origin rpy="0 0 0" xyz="-0.2422 0.0 0.0265" />
            <inertia ixx="0.00399632" ixy="-1.365e-05" ixz="0.00137272" iyy="0.07879254" iyz="-6.6e-06" izz="0.0784851" />
        </inertial>
    </link>
    <link name="arm_wrist_1_link">
        <visual>
            <!-- TODO: Move this to a parameter -->
            <origin rpy="1.5707963267948966 0 0" xyz="0 0 -0.127" />
            <geometry>
                <mesh filename="package://ur_description/meshes/ur5e/visual/wrist1.dae" />
            </geometry>
            <material name="LightGrey">
                <color rgba="0.7 0.7 0.7 1.0" />
            </material>
        </visual>
        <collision>
            <origin rpy="1.5707963267948966 0 0" xyz="0 0 -0.127" />
            <geometry>
                <mesh filename="package://ur_description/meshes/ur5e/collision/wrist1.stl" />
            </geometry>
        </collision>
        <inertial>
            <mass value="1.37" />
            <origin rpy="1.570796326794897 0 0" xyz="0.0 -0.01634 -0.0018" />
            <inertia ixx="0.00165491" ixy="-2.82e-06" ixz="-4.38e-06" iyy="0.00135962" iyz="0.00010157" izz="0.00126279" />
        </inertial>
    </link>
    <link name="arm_wrist_2_link">
        <visual>
            <origin rpy="0 0 0" xyz="0 0 -0.0997" />
            <geometry>
                <mesh filename="package://ur_description/meshes/ur5e/visual/wrist2.dae" />
            </geometry>
            <material name="LightGrey">
                <color rgba="0.7 0.7 0.7 1.0" />
            </material>
        </visual>
        <collision>
            <origin rpy="0 0 0" xyz="0 0 -0.0997" />
            <geometry>
                <mesh filename="package://ur_description/meshes/ur5e/collision/wrist2.stl" />
            </geometry>
        </collision>
        <inertial>
            <mass value="1.3" />
            <origin rpy="-1.570796326794897 0 0" xyz="0.0 0.01634 -0.0018" />
            <inertia ixx="0.00135617" ixy="-2.74e-06" ixz="4.44e-06" iyy="0.00127827" iyz="-5.048e-05" izz="0.00096614" />
        </inertial>
    </link>
    <link name="arm_wrist_3_link">
        <visual>
            <origin rpy="1.5707963267948966 0 0" xyz="0 0 -0.0989" />
            <geometry>
                <mesh filename="package://ur_description/meshes/ur5e/visual/wrist3.dae" />
            </geometry>
            <material name="LightGrey">
                <color rgba="0.7 0.7 0.7 1.0" />
            </material>
        </visual>
        <collision>
            <origin rpy="1.5707963267948966 0 0" xyz="0 0 -0.0989" />
            <geometry>
                <mesh filename="package://ur_description/meshes/ur5e/collision/wrist3.stl" />
            </geometry>
        </collision>
        <inertial>
            <mass value="0.365" />
            <origin rpy="0 0 0" xyz="0.0 0.0 -0.001159" />
            <inertia ixx="0.00018694" ixy="6e-08" ixz="-1.7e-07" iyy="0.00018908" iyz="-9.2e-07" izz="0.00025756" />
        </inertial>
    </link>
    <!-- joints: main serial chain -->
    <joint name="arm_base_link-base_link_inertia" type="fixed">
        <parent link="arm_base_link" />
        <child link="arm_base_link_inertia" />
        <!-- 'base_link' is REP-103 aligned (so X+ forward), while the internal
           frames of the robot/controller have X+ pointing backwards.
           Use the joint between 'base_link' and 'base_link_inertia' (a dummy
           link/frame) to introduce the necessary rotation over Z (of pi rad).
      -->
        <origin rpy="0 0 3.141592653589793" xyz="0 0 0" />
    </joint>
    <joint name="arm_shoulder_pan_joint" type="revolute">
        <parent link="arm_base_link_inertia" />
        <child link="arm_shoulder_link" />
        <origin rpy="0 0 6.517678258211035e-09" xyz="0 0 0.16255194936954" />
        <axis xyz="0 0 1" />
        <limit effort="150.0" lower="-6.283185307179586" upper="6.283185307179586" velocity="3.141592653589793" />
        <safety_controller k_position="20" k_velocity="0.0" soft_lower_limit="-6.133185307179586" soft_upper_limit="6.133185307179586" />
        <dynamics damping="0" friction="0" />
    </joint>
    <joint name="arm_shoulder_lift_joint" type="revolute">
        <parent link="arm_shoulder_link" />
        <child link="arm_upper_arm_link" />
        <origin rpy="1.571049621366859 0 4.102791795435726e-06" xyz="0.00017633281638345446 0 0" />
        <axis xyz="0 0 1" />
        <limit effort="150.0" lower="-6.283185307179586" upper="6.283185307179586" velocity="3.141592653589793" />
        <safety_controller k_position="20" k_velocity="0.0" soft_lower_limit="-6.133185307179586" soft_upper_limit="6.133185307179586" />
        <dynamics damping="0" friction="0" />
    </joint>
    <joint name="arm_elbow_joint" type="revolute">
        <parent link="arm_upper_arm_link" />
        <child link="arm_forearm_link" />
        <origin rpy="3.1409684945380465 -3.141462970503125 -3.141591366706805" xyz="-0.42507411305917414 0 0" />
        <axis xyz="0 0 1" />
        <limit effort="150.0" lower="-3.141592653589793" upper="3.141592653589793" velocity="3.141592653589793" />
        <safety_controller k_position="20" k_velocity="0.0" soft_lower_limit="-2.991592653589793" soft_upper_limit="2.991592653589793" />
        <dynamics damping="0" friction="0" />
    </joint>
    <joint name="arm_wrist_1_joint" type="revolute">
        <parent link="arm_forearm_link" />
        <child link="arm_wrist_1_link" />
        <origin rpy="0.007946067819602057 -0.00012154997533656013 -4.22448977201621e-06" xyz="-0.39227981068741574 -0.0010591080056578188 0.13328425315731332" />
        <axis xyz="0 0 1" />
        <limit effort="28.0" lower="-6.283185307179586" upper="6.283185307179586" velocity="3.141592653589793" />
        <safety_controller k_position="20" k_velocity="0.0" soft_lower_limit="-6.133185307179586" soft_upper_limit="6.133185307179586" />
        <dynamics damping="0" friction="0" />
    </joint>
    <joint name="arm_wrist_2_joint" type="revolute">
        <parent link="arm_wrist_1_link" />
        <child link="arm_wrist_2_link" />
        <origin rpy="1.5702338654608972 0 3.0489132378172523e-07" xyz="-0.00016549115882340316 -0.09957782549637102 5.600868247180796e-05" />
        <axis xyz="0 0 1" />
        <limit effort="28.0" lower="-6.283185307179586" upper="6.283185307179586" velocity="3.141592653589793" />
        <safety_controller k_position="20" k_velocity="0.0" soft_lower_limit="-6.133185307179586" soft_upper_limit="6.133185307179586" />
        <dynamics damping="0" friction="0" />
    </joint>
    <joint name="arm_wrist_3_joint" type="revolute">
        <parent link="arm_wrist_2_link" />
        <child link="arm_wrist_3_link" />
        <origin rpy="1.5709925101486988 3.141592653589793 -3.141592508506073" xyz="4.843723697583229e-05 0.0994375081974557 1.9507984102193143e-05" />
        <axis xyz="0 0 1" />
        <limit effort="28.0" lower="-6.283185307179586" upper="6.283185307179586" velocity="3.141592653589793" />
        <safety_controller k_position="20" k_velocity="0.0" soft_lower_limit="-6.133185307179586" soft_upper_limit="6.133185307179586" />
        <dynamics damping="0" friction="0" />
    </joint>
    <!-- ROS-Industrial 'base' frame: base_link to UR 'Base' Coordinates transform -->
    <link name="arm_base" />
    <joint name="arm_base_link-base_fixed_joint" type="fixed">
        <!-- Note the rotation over Z of pi radians: as base_link is REP-103
           aligned (ie: has X+ forward, Y+ left and Z+ up), this is needed
           to correctly align 'base' with the 'Base' coordinate system of
           the UR controller.
      -->
        <origin rpy="0 0 3.141592653589793" xyz="0 0 0" />
        <parent link="arm_base_link" />
        <child link="arm_base" />
    </joint>
    <!-- ROS-Industrial 'flange' frame: attachment point for EEF models -->
    <link name="arm_flange" />
    <joint name="arm_wrist_3-flange" type="fixed">
        <parent link="arm_wrist_3_link" />
        <child link="arm_flange" />
        <origin rpy="0 -1.5707963267948966 -1.5707963267948966" xyz="0 0 0" />
    </joint>
    <!-- ROS-Industrial 'tool0' frame: all-zeros tool frame -->
    <link name="arm_tool0" />
    <joint name="arm_flange-tool0" type="fixed">
        <!-- default toolframe: X+ left, Y+ up, Z+ front -->
        <origin rpy="1.5707963267948966 0 1.5707963267948966" xyz="0 0 0" />
        <parent link="arm_flange" />
        <child link="arm_tool0" />
    </joint>
    <material name="mount_gray">
        <color rgba="0.4 0.4 0.4 1" />
    </material>
    <link name="mount">
        <visual>
            <geometry>
                <cylinder length="0.8" radius="0.07" />
            </geometry>
            <origin rpy="0 0 0" xyz="0 0 0.4" />
            <material name="mount_gray" />
        </visual>
        <visual>
            <geometry>
                <cylinder length="0.013" radius="0.1" />
            </geometry>
            <origin rpy="0 0 0" xyz="0 0 0.7935000000000001" />
            <material name="mount_gray" />
        </visual>
        <visual>
            <geometry>
                <box size="1.0 0.05 0.05" />
            </geometry>
            <origin rpy="0 0 1.5707963267948966" xyz="0 0 0.025" />
            <material name="mount_gray" />
        </visual>
        <visual>
            <geometry>
                <box size="1.0 0.05 0.05" />
            </geometry>
            <origin rpy="0 0 2.617993877991494" xyz="0 0 0.025" />
            <material name="mount_gray" />
        </visual>
        <visual>
            <geometry>
                <box size="1.0 0.05 0.05" />
            </geometry>
            <origin rpy="0 0 0.5235987755982989" xyz="0 0 0.025" />
            <material name="mount_gray" />
        </visual>
        <collision>
            <geometry>
                <cylinder length="0.8" radius="0.15" />
            </geometry>
            <origin rpy="0 0 0" xyz="0 0 0.4" />
        </collision>
        <inertial>
            <mass value="0.1" />
            <origin xyz="0 0 0" rpy="0 0 0" />
            <inertia ixx="0.03" iyy="0.03" izz="0.03" ixy="0.0" ixz="0.0" iyz="0.0" />
        </inertial>
    </link>
    <joint name="mount_to_arm_base" type="fixed">
        <parent link="mount" />
        <child link="arm_base_link" />
        <origin rpy="0 0 -1.5707963267948966" xyz="0 0 0.8" />
    </joint>
    <link name="base" />
    <joint name="base_to_mount" type="fixed">
        <parent link="base" />
        <child link="mount" />
        <origin rpy="0 0 0" xyz="0 0 0.0" />
    </joint>
    <link name="control_box">
        <visual>
            <geometry>
                <box size="0.32 0.6 0.5" />
            </geometry>
            <origin rpy="0 0 0" xyz="0.0 0 0.0" />
            <material name="LightGrey" />
        </visual>
        <collision>
            <geometry>
                <box size="0.32 0.6 0.5" />
            </geometry>
            <origin rpy="0 0 0" xyz="0.0 0 0.0" />
        </collision>
        <inertial>
            <mass value="0.1" />
            <origin xyz="0 0 0" rpy="0 0 0" />
            <inertia ixx="0.03" iyy="0.03" izz="0.03" ixy="0.0" ixz="0.0" iyz="0.0" />
        </inertial>
    </link>
    <joint name="mount_to_control_box" type="fixed">
        <parent link="mount" />
        <child link="control_box" />
        <origin rpy="0 0 0" xyz="-0.3 0.0 0.5" />
    </joint>
    <link name="arm_flange_safety">
        <!-- https://forum.universal-robots.com/t/error-c403a0-danger-of-clamping-between-the-robot-lower-arm-and-tool/16142/2 -->
        <visual>
            <geometry>
                <sphere radius="0" />
            </geometry>
            <origin rpy="0 0 0" xyz="0 0 0.0" />
            <material name="transparent_gray">
                <color rgba="0.5 0.5 0.5 .3" />
            </material>
        </visual>
        <collision>
            <geometry>
                <sphere radius="0.0655" />
            </geometry>
            <origin rpy="0 0 0" xyz="0 0 0.0" />
        </collision>
        <inertial>
            <mass value="0.1" />
            <origin xyz="0 0 0" rpy="0 0 0" />
            <inertia ixx="0.03" iyy="0.03" izz="0.03" ixy="0.0" ixz="0.0" iyz="0.0" />
        </inertial>
    </link>
    <joint name="arm_flange_safety_joint" type="fixed">
        <parent link="arm_flange" />
        <child link="arm_flange_safety" />
        <origin rpy="0 0 0" xyz="0 0 0.0" />
    </joint>
    <material name="wall_gray">
        <color rgba="0.7 0.7 0.7 1" />
    </material>
    <material name="clearance_volume">
        <color rgba="0.6 0.4 0.2 0.2" />
    </material>
    <link name="wall">
        <visual>
            <geometry>
                <box size="0.1 4.5 2.0" />
            </geometry>
            <origin rpy="0 0 0" xyz="0 0 1.0" />
            <material name="wall_gray" />
        </visual>
        <collision>
            <geometry>
                <box size="0.1 4.0 2.0" />
            </geometry>
            <origin rpy="0 0 0" xyz="0 0 1.0" />
        </collision>
        <inertial>
            <mass value="0.1" />
            <origin xyz="0 0 0" rpy="0 0 0" />
            <inertia ixx="0.03" iyy="0.03" izz="0.03" ixy="0.0" ixz="0.0" iyz="0.0" />
        </inertial>
    </link>
    <joint name="base_to_wall" type="fixed">
        <parent link="base" />
        <child link="wall" />
        <origin rpy="0 0 0" xyz="-.5 0 0" />
    </joint>
    <material name="table_brown">
        <color rgba="0.6 0.4 0.2 1" />
    </material>
    <material name="table_black">
        <color rgba="0.1 0.1 0.1 1" />
    </material>
    <link name="table">
        <collision>
            <geometry>
                <box size="0.8 0.8 0.72" />
            </geometry>
            <origin rpy="0 0 0" xyz="0 0 0.36" />
        </collision>
        <!-- Front right leg -->
        <visual>
            <geometry>
                <cylinder length="0.69" radius="0.02" />
            </geometry>
            <origin rpy="0 0 0" xyz="0.38 0.38 0.345" />
            <material name="table_black" />
        </visual>
        <!-- Front left leg -->
        <visual>
            <geometry>
                <cylinder length="0.69" radius="0.02" />
            </geometry>
            <origin rpy="0 0 0" xyz="-0.38 0.38 0.345" />
            <material name="table_black" />
        </visual>
        <!-- Back right leg -->
        <visual>
            <geometry>
                <cylinder length="0.69" radius="0.02" />
            </geometry>
            <origin rpy="0 0 0" xyz="0.38 -0.38 0.345" />
            <material name="table_black" />
        </visual>
        <!-- Back left leg -->
        <visual>
            <geometry>
                <cylinder length="0.69" radius="0.02" />
            </geometry>
            <origin rpy="0 0 0" xyz="-0.38 -0.38 0.345" />
            <material name="table_black" />
        </visual>
        <visual>
            <geometry>
                <box size="0.8 0.8 0.03" />
            </geometry>
            <origin rpy="0 0 0" xyz="0 0 0.705" />
            <material name="table_brown" />
        </visual>
        <inertial>
            <mass value="0.1" />
            <origin xyz="0 0 0" rpy="0 0 0" />
            <inertia ixx="0.03" iyy="0.03" izz="0.03" ixy="0.0" ixz="0.0" iyz="0.0" />
        </inertial>
    </link>
    <link name="table_top" />
    <joint name="table_top_joint" type="fixed">
        <parent link="table" />
        <child link="table_top" />
        <origin rpy="0 0 0" xyz="0 0 0.72" />
    </joint>
    <joint name="base_to_table" type="fixed">
        <parent link="base" />
        <child link="table" />
        <origin rpy="0 0 0" xyz="0.85 0 0.0" />
    </joint>
    <material name="operator_table_brown">
        <color rgba="0.6 0.4 0.2 1" />
    </material>
    <material name="operator_table_black">
        <color rgba="0.1 0.1 0.1 1" />
    </material>
    <link name="operator_table">
        <collision>
            <geometry>
                <box size="0.8 1.6 0.72" />
            </geometry>
            <origin rpy="0 0 0" xyz="0 0 0.36" />
        </collision>
        <!-- Front right leg -->
        <visual>
            <geometry>
                <cylinder length="0.69" radius="0.02" />
            </geometry>
            <origin rpy="0 0 0" xyz="0.38 0.78 0.345" />
            <material name="operator_table_black" />
        </visual>
        <!-- Front left leg -->
        <visual>
            <geometry>
                <cylinder length="0.69" radius="0.02" />
            </geometry>
            <origin rpy="0 0 0" xyz="-0.38 0.78 0.345" />
            <material name="operator_table_black" />
        </visual>
        <!-- Back right leg -->
        <visual>
            <geometry>
                <cylinder length="0.69" radius="0.02" />
            </geometry>
            <origin rpy="0 0 0" xyz="0.38 -0.78 0.345" />
            <material name="operator_table_black" />
        </visual>
        <!-- Back left leg -->
        <visual>
            <geometry>
                <cylinder length="0.69" radius="0.02" />
            </geometry>
            <origin rpy="0 0 0" xyz="-0.38 -0.78 0.345" />
            <material name="operator_table_black" />
        </visual>
        <visual>
            <geometry>
                <box size="0.8 1.6 0.03" />
            </geometry>
            <origin rpy="0 0 0" xyz="0 0 0.705" />
            <material name="operator_table_brown" />
        </visual>
        <inertial>
            <mass value="0.1" />
            <origin xyz="0 0 0" rpy="0 0 0" />
            <inertia ixx="0.03" iyy="0.03" izz="0.03" ixy="0.0" ixz="0.0" iyz="0.0" />
        </inertial>
    </link>
    <link name="operator_table_top" />
    <joint name="operator_table_top_joint" type="fixed">
        <parent link="operator_table" />
        <child link="operator_table_top" />
        <origin rpy="0 0 0" xyz="0 0 0.72" />
    </joint>
    <joint name="base_to_operator_table" type="fixed">
        <parent link="base" />
        <child link="operator_table" />
        <origin rpy="0 0 0" xyz="0.0 1.4500000000000002 0.0" />
    </joint>
    <link name="operator_clearance">
        <visual>
            <geometry>
                <box size="0.8 1.6 0.55" />
            </geometry>
            <origin rpy="0 0 0" xyz="0 0 0.0" />
            <material name="clearance_volume" />
        </visual>
    </link>
    <joint name="operator_clearance_joint" type="fixed">
        <parent link="operator_table_top" />
        <child link="operator_clearance" />
        <origin rpy="0 0 0" xyz="0.0 0.0 0.275" />
    </joint>
    <gazebo>
        <plugin name="gazebo_ros_control" filename="libgazebo_ros_control.so">
            <robotNamespace>/</robotNamespace>
        </plugin>
    </gazebo>
</robot>

